Traceback (most recent call last):
  File "/opt/anaconda3/lib/python3.8/site-packages/jupyter_cache/executors/utils.py", line 51, in single_nb_execution
    executenb(
  File "/opt/anaconda3/lib/python3.8/site-packages/nbclient/client.py", line 1112, in execute
    return NotebookClient(nb=nb, resources=resources, km=km, **kwargs).execute()
  File "/opt/anaconda3/lib/python3.8/site-packages/nbclient/util.py", line 74, in wrapped
    return just_run(coro(*args, **kwargs))
  File "/opt/anaconda3/lib/python3.8/site-packages/nbclient/util.py", line 53, in just_run
    return loop.run_until_complete(coro)
  File "/opt/anaconda3/lib/python3.8/asyncio/base_events.py", line 616, in run_until_complete
    return future.result()
  File "/opt/anaconda3/lib/python3.8/site-packages/nbclient/client.py", line 553, in async_execute
    await self.async_execute_cell(
  File "/opt/anaconda3/lib/python3.8/site-packages/nbclient/client.py", line 857, in async_execute_cell
    self._check_raise_for_error(cell, exec_reply)
  File "/opt/anaconda3/lib/python3.8/site-packages/nbclient/client.py", line 760, in _check_raise_for_error
    raise CellExecutionError.from_cell_and_msg(cell, exec_reply_content)
nbclient.exceptions.CellExecutionError: An error occurred while executing the following cell:
------------------
import numpy as np
import numpy.random as npr
import pandas as pd

%matplotlib inline
from pylab import mpl, plt
plt.style.use('seaborn')
plt.rcParams['savefig.dpi'] = 300
plt.rcParams['font.family'] = 'serif'

import csv, math, random
import tables as tb

import configparser
c = configparser.ConfigParser()
c.read('pyalgo.cfg')

import quandl as q
q.ApiConfig.api_key = c['quandl']['api_key']
------------------

[0;31m---------------------------------------------------------------------------[0m
[0;31mKeyError[0m                                  Traceback (most recent call last)
[0;32m<ipython-input-1-050f7449bf9e>[0m in [0;36m<module>[0;34m[0m
[1;32m     17[0m [0;34m[0m[0m
[1;32m     18[0m [0;32mimport[0m [0mquandl[0m [0;32mas[0m [0mq[0m[0;34m[0m[0;34m[0m[0m
[0;32m---> 19[0;31m [0mq[0m[0;34m.[0m[0mApiConfig[0m[0;34m.[0m[0mapi_key[0m [0;34m=[0m [0mc[0m[0;34m[[0m[0;34m'quandl'[0m[0;34m][0m[0;34m[[0m[0;34m'api_key'[0m[0;34m][0m[0;34m[0m[0;34m[0m[0m
[0m
[0;32m/opt/anaconda3/lib/python3.8/configparser.py[0m in [0;36m__getitem__[0;34m(self, key)[0m
[1;32m    958[0m     [0;32mdef[0m [0m__getitem__[0m[0;34m([0m[0mself[0m[0;34m,[0m [0mkey[0m[0;34m)[0m[0;34m:[0m[0;34m[0m[0;34m[0m[0m
[1;32m    959[0m         [0;32mif[0m [0mkey[0m [0;34m!=[0m [0mself[0m[0;34m.[0m[0mdefault_section[0m [0;32mand[0m [0;32mnot[0m [0mself[0m[0;34m.[0m[0mhas_section[0m[0;34m([0m[0mkey[0m[0;34m)[0m[0;34m:[0m[0;34m[0m[0;34m[0m[0m
[0;32m--> 960[0;31m             [0;32mraise[0m [0mKeyError[0m[0;34m([0m[0mkey[0m[0;34m)[0m[0;34m[0m[0;34m[0m[0m
[0m[1;32m    961[0m         [0;32mreturn[0m [0mself[0m[0;34m.[0m[0m_proxies[0m[0;34m[[0m[0mkey[0m[0;34m][0m[0;34m[0m[0;34m[0m[0m
[1;32m    962[0m [0;34m[0m[0m

[0;31mKeyError[0m: 'quandl'
KeyError: 'quandl'

